Workbook

Sheet Técnica
A1: Estudo de Viabilidade
A3: Técnica
A4: Colaborador(a) | B4: Tecnologia | C4: Atividade | D4: Domínio (%)*
A5: Pedro Vinícius | B5: Html | Css | C5: Gestão | D5: 65
A6: Pedro Gomes | B6: Word | Canva | C6: Analista | D6: 80
A7: Enzo Ramos | B7: Html | Css | C7: Front end | D7: 90
A8: Lucas Lima | B8: Figma | Css | C8: Protótipo | D8: 70
A9: Vinicius Pereira | B9: Figma | Canva | C9: Protótipo | D9: 75
A10: Mateus Mattos | B10: Canva | C10: Logotipo | D10: 30
A12: * O percentual de domínio refere-se ao conhecimento necessário para o desenvolvimento específico da atividade, não ao conhecimento total da tecnologia.

Sheet Custo
A3: Custo - 9 Meses
A4: Colaborador(a) | B4: Função | C4: Total Mensal | D4: 9 Meses
A5: Pedro Gomes | B5: Gestão de projetos | C5: 3400 | D5: =C5*9 -> 30600
A6: Enzo Ramos | B6: Dev | C6: 2600 | D6: =C6*9 -> 23400
A7: Pedro Vinicius | B7: Gestão de Projeto | C7: 3400 | D7: =C7*9 -> 30600
A8: Vinicius Pereira | B8: Designer | C8: 2600 | D8: =C8*9 -> 23400
A9: Lucas Oliveira | B9: Designer | C9: 2200 | D9: =C9*9 -> 19800
A10: Mateus Mattos | B10: Designer | C10: 2200 | D10: =C10*9 -> 19800
A11: Total dos Custos com Pessoal | C11: =SUM(C5,C7,C6,C8,C9,C10) -> 16400 | D11: =SUM(D5,D6,D7,D8,D9,D10) -> 147600
A13: Custos Fixos*
A14: Despesas | B14: Fev | C14: Mar | D14: Total
A15: Aluguel | B15: 900 | C15: 900 | D15: =SUM(B15:C15) -> 1800
A16: Luz | B16: 300 | C16: 270 | D16: =SUM(B16:C16) -> 570
A17: Água | B17: 60 | C17: 60 | D17: =SUM(B17:C17) -> 120
A18: Refeições | B18: 79 | C18: 75 | D18: =SUM(B18:C18) -> 154
A19: Transporte | B19: 250 | C19: 250 | D19: =SUM(B19:C19) -> 500
A20: Cursos** | B20: 50 | C20: 50 | D20: =SUM(B20:C20) -> 100
A21: Notebooks*** | B21: 750 | C21: 750 | D21: =SUM(B21:C21) -> 1500
A22: Outras | C22: 400 | D22: =SUM(B22:C22) -> 400
A23: Sub-total | B23: =SUM(B15:B22) -> 2389 | C23: =SUM(C15:C22) -> 2755 | D23: =SUM(B23:C23) -> 5144
A25: Total dos custos do Projeto: | D25: =SUM(D11+D23) -> 152744
A29: Estudo de Viabilidade
A31: Custo Mensal
A32: Colaborador(a) | B32: Função | C32: Valor Hora* | D32: Qtde. Horas** | E32: Total
A33: Enzo Ramos | B33: Dev | C33: 27 | D33: =SUM(Prazo!C7,Prazo!C17,Prazo!C27,Prazo!C37,Prazo!C47,Prazo!C57,Prazo!C67,Prazo!C77,Prazo!C87) -> 24 | E33: =PRODUCT(C33:D33) -> 648
A34: Lucas Oliveira | B34: Designer | C34: 20 | D34: =SUM(Prazo!C48,Prazo!C38,Prazo!C28,Prazo!C18,Prazo!C8,Prazo!C58,Prazo!C68,Prazo!C78,Prazo!C88) -> 17 | E34: =PRODUCT(C34:D34) -> 340
A35: Pedro Gomes | B35: Analista | C35: 29 | D35: =SUM(Prazo!C6,Prazo!C16,Prazo!C26,Prazo!C36,Prazo!C46,Prazo!C56,Prazo!C66,Prazo!C76,Prazo!C86) -> 18 | E35: =PRODUCT(C35:D35) -> 522
A36: Pedro Vinicius | B36: Gestão de projetos | C36: 30 | D36: =SUM(Prazo!C5,Prazo!C15,Prazo!C25,Prazo!C35,Prazo!C45,Prazo!C55,Prazo!C65,Prazo!C75,Prazo!C85) -> 9 | E36: =PRODUCT(C36:D36) -> 270
A37: Vinicius Pereira | B37: Designer | C37: 20 | D37: =SUM(Prazo!C9,Prazo!C19,Prazo!C29,Prazo!C39,Prazo!C49,Prazo!C59,Prazo!C69,Prazo!C79,Prazo!C89) -> 14 | E37: =PRODUCT(C37:D37) -> 280
A38: Mateus Mattos | B38: Designer | C38: 20 | D38: =SUM(Prazo!C10,Prazo!C20,Prazo!C30,Prazo!C40,Prazo!C50,Prazo!C60,Prazo!C70,Prazo!C80,Prazo!C90) -> 7 | E38: =PRODUCT(C38:D38) -> 140
A39: Total de Horas: | C39: =SUM(C34:C38) -> 119 | D39: =SUM(D34:D38) -> 65 | E39: =SUM(E34:E38) -> 1552

Sheet Planilha2

Sheet Prazo
A1: Estudo de Viabilidade
A3: Prazo
A4: Mês | B4: Colaborador(a) | C4: Horas por Semana | D4: Horas/aula | E4: Total por Semana | F4: Total por mês
A5: Fev | B5: Pedro Vinícius | C5: 0 | D5: 4 | E5: =SUM(C5:D5) -> 4 | F5: 9
B6: Pedro Henrique | C6: 0 | D6: 4 | E6: =SUM(C6:D6) -> 4 | F6: 9
B7: Enzo Ramos | C7: 0 | D7: 4 | E7: =SUM(C7:D7) -> 4 | F7: 9
B8: Lucas Oliveira | C8: 0 | D8: 4 | E8: =SUM(C8:D8) -> 4 | F8: 9
B9: Vinícius | C9: 0 | D9: 4 | E9: =SUM(C9:D9) -> 4 | F9: 9
B10: Mateus Mattos | C10: 0 | D10: 4 | E10: =SUM(C10:D10) -> 4 | F10: 9
A11: Total de Horas | C11: 0 | D11: =SUM(D5:D10) -> 24 | E11: =SUM(E5:E10) -> 24 | F11: =SUM(F5:F10) -> 54
A13: Prazo
A14: Mês | B14: Colaborador(a) | C14: Horas por Semana | D14: Horas/aula | E14: Total por Semana | F14: Total por mês
A15: Mar | B15: Pedro Vinícius | C15: 1 | D15: 4 | E15: =SUM(C15:D15) -> 5 | F15: =E15*4.5 -> 22.5
B16: Pedro Henrique | C16: 1 | D16: 4 | E16: =SUM(C16:D16) -> 5 | F16: =E16*4.5 -> 22.5
B17: Enzo Ramos | C17: 2 | D17: 4 | E17: =SUM(C17:D17) -> 6 | F17: =E17*4.5 -> 27
B18: Lucas Oliveira | C18: 1 | D18: 4 | E18: =SUM(C18:D18) -> 5 | F18: =E18*4.5 -> 22.5
B19: Vinícius | C19: 1 | D19: 4 | E19: =SUM(C19:D19) -> 5 | F19: =E19*4.5 -> 22.5
B20: Mateus Mattos | C20: 1 | D20: 4 | E20: =SUM(C20:D20) -> 5 | F20: =E20*4.5 -> 22.5
A21: Total de Horas | C21: =SUM(C15:C20) -> 7 | D21: =SUM(D15:D20) -> 24 | E21: =SUM(E15:E20) -> 31 | F21: =F20+F19+F18+F17+F16+F15 -> 139.5
A23: Prazo
A24: Mês | B24: Colaborador(a) | C24: Horas por Semana | D24: Horas/aula | E24: Total por Semana | F24: Total por mês
A25: Abr | B25: Pedro Vinícius | C25: 2 | D25: 4 | E25: =SUM(C25:D25) -> 6 | F25: =E25*4.5 -> 27
B26: Pedro Henrique | C26: 2 | D26: 4 | E26: =SUM(C26:D26) -> 6 | F26: =E26*4.5 -> 27
B27: Enzo Ramos | C27: 3 | D27: 4 | E27: =SUM(C27:D27) -> 7 | F27: =E27*4.5 -> 31.5
B28: Lucas Oliveira | C28: 2 | D28: 4 | E28: =SUM(C28:D28) -> 6 | F28: =E28*4.5 -> 27
B29: Vinícius | C29: 2 | D29: 4 | E29: =SUM(C29:D29) -> 6 | F29: =E29*4.5 -> 27
B30: Mateus Mattos | C30: 1 | D30: 4 | E30: =SUM(C30:D30) -> 5 | F30: =E30*4.5 -> 22.5
A31: Total de Horas | C31: =SUM(C25:C30) -> 12 | D31: =SUM(D25:D30) -> 24 | E31: =SUM(E25:E30) -> 36 | F31: =SUM(F25:F30) -> 162
A33: Prazo
A34: Mês | B34: Colaborador(a) | C34: Horas por Semana | D34: Horas/aula | E34: Total por Semana | F34: Total por mês
A35: Mai | B35: Pedro Vinícius | C35: 1 | D35: 4 | E35: =SUM(C35:D35) -> 5 | F35: =E35*4.5 -> 22.5
B36: Pedro Henrique | C36: 2 | D36: 4 | E36: =SUM(C36:D36) -> 6 | F36: =E36*4.5 -> 27
B37: Enzo Ramos | C37: 3 | D37: 4 | E37: =SUM(C37:D37) -> 7 | F37: =E37*4.5 -> 31.5
B38: Lucas Oliveira | C38: 3 | D38: 4 | E38: =SUM(C38:D38) -> 7 | F38: =E38*4.5 -> 31.5
B39: Vinícius | C39: 2 | D39: 4 | E39: =SUM(C39:D39) -> 6 | F39: =E39*4.5 -> 27
B40: Mateus Mattos | C40: 0 | D40: 4 | E40: =SUM(C40:D40) -> 4 | F40: =E40*4.5 -> 18
A41: Total de Horas | C41: =SUM(C35:C40) -> 11 | D41: =SUM(D35:D40) -> 24 | E41: =SUM(E35:E40) -> 35 | F41: 94.5
A43: Prazo
A44: Mês | B44: Colaborador(a) | C44: Horas por Semana | D44: Horas/aula | E44: Total por Semana | F44: Total por mês
A45: Jun | B45: Pedro Vinícius | C45: 1 | D45: 4 | E45: =SUM(C45:D45) -> 5 | F45: =E45*4.5 -> 22.5
...
